Workbook

Sheet Weights
A1: Criteria Weights and Type (Benefit / Cost) used in TOPSIS
A3: Criterion | B3: Weight | C3: Type | D3: Ideal-Best Rule
A4: Cost | B4: 0.10804421 | C4: Cost | D4: MIN = best (lower cost preferred)
A5: Reliability | B5: 0.12811349 | C5: Benefit | D5: MAX = best (higher is preferred)
A6: Ease of implementation | B6: 0.12267004 | C6: Benefit | D6: MAX = best (higher is preferred)
A7: Compatibility | B7: 0.12712377 | C7: Benefit | D7: MAX = best (higher is preferred)
A8: Real time information | B8: 0.12921317 | C8: Benefit | D8: MAX = best (higher is preferred)
A9: Efficiency | B9: 0.1305328 | C9: Benefit | D9: MAX = best (higher is preferred)
A10: Risk Reduction | B10: 0.126299 | C10: Benefit | D10: MAX = best (higher is preferred)
A11: Sustainability | B11: 0.12800352 | C11: Benefit | D11: MAX = best (higher is preferred)
A12: Total | B12: =SUM(B4:B11) -> 1

Sheet 1. Decision Matrix
A1: TOPSIS Step 0 — Decision Matrix (25 IoT Tool × SCM Technique combinations × 8 criteria)
A2: Values are mean scores (scale 1–5) from the 58-expert integrated IoT–SCM assessment.
A4: No. | B4: IoT Tool | C4: SCM Technique | D4: Cost | E4: Reliability | F4: Ease of implementation | G4: Compatibility | H4: Real time information | I4: Efficiency | J4: Risk Reduction | K4: Sustainability
A5: 1 | B5: IoT Sensors | C5: Procurement Management | D5: 3.3275862 | E5: 3.9568966 | F5: 3.9051724 | G5: 3.9224138 | H5: 3.8534483 | I5: 3.9827586 | J5: 3.9310345 | K5: 3.8706897
A6: 2 | B6: IoT Sensors | C6: Inventory Management | D6: 3.3448276 | E6: 4.0172414 | F6: 3.887931 | G6: 3.9913793 | H6: 4.0517241 | I6: 4.0775862 | J6: 4 | K6: 3.9827586
A7: 3 | B7: IoT Sensors | C7: Logistics Management | D7: 3.2844828 | E7: 4.0258621 | F7: 3.8965517 | G7: 3.9224138 | H7: 4.0862069 | I7: 4.0517241 | J7: 3.9827586 | K7: 3.9051724
A8: 4 | B8: IoT Sensors | C8: Supplier Management | D8: 3.3362069 | E8: 3.9827586 | F8: 3.9310345 | G8: 3.9310345 | H8: 3.9655172 | I8: 3.9913793 | J8: 3.9396552 | K8: 3.9224138
A9: 5 | B9: IoT Sensors | C9: Just-in-Time | D9: 3.3793103 | E9: 3.9741379 | F9: 3.7844828 | G9: 3.8706897 | H9: 4.112069 | I9: 4 | J9: 3.9655172 | K9: 4.0086207
A10: 6 | B10: RFID | C10: Procurement Management | D10: 3.5775862 | E10: 3.9568966 | F10: 3.9655172 | G10: 3.9655172 | H10: 3.8534483 | I10: 4.0431034 | J10: 3.9482759 | K10: 3.9568966
A11: 7 | B11: RFID | C11: Inventory Management | D11: 3.5948276 | E11: 4.0172414 | F11: 3.9482759 | G11: 4.0344828 | H11: 4.0517241 | I11: 4.137931 | J11: 4.0172414 | K11: 4.0689655
A12: 8 | B12: RFID | C12: Logistics Management | D12: 3.5344828 | E12: 4.0258621 | F12: 3.9568966 | G12: 3.9655172 | H12: 4.0862069 | I12: 4.112069 | J12: 4 | K12: 3.9913793
A13: 9 | B13: RFID | C13: Supplier Management | D13: 3.5862069 | E13: 3.9827586 | F13: 3.9913793 | G13: 3.9741379 | H13: 3.9655172 | I13: 4.0517241 | J13: 3.9568966 | K13: 4.0086207
A14: 10 | B14: RFID | C14: Just-in-Time | D14: 3.6293103 | E14: 3.9741379 | F14: 3.8448276 | G14: 3.9137931 | H14: 4.112069 | I14: 4.0603448 | J14: 3.9827586 | K14: 4.0948276
A15: 11 | B15: GPS | C15: Procurement Management | D15: 3.5172414 | E15: 4.0603448 | F15: 3.9913793 | G15: 3.9655172 | H15: 3.9137931 | I15: 4.0689655 | J15: 3.9051724 | K15: 3.9568966
A16: 12 | B16: GPS | C16: Inventory Management | D16: 3.5344828 | E16: 4.1206897 | F16: 3.9741379 | G16: 4.0344828 | H16: 4.112069 | I16: 4.1637931 | J16: 3.9741379 | K16: 4.0689655
... A29: 25 | B29: Cloud computing | C29: Just-in-Time | D29: 3.2758621 | E29: 3.9827586 | F29: 3.7241379 | G29: 3.9655172 | H29: 4.1896552 | I29: 4.0775862 | J29: 3.9482759 | K29: 4.0862069

Sheet 2. Normalized Matrix
A1: TOPSIS Step 1 — Vector-Normalized Decision Matrix
A2: r_ij = x_ij / SQRT(SUM(x_ij^2)) for each criterion column j, computed across all 25 alternatives.
A4: No. | B4: IoT Tool | C4: SCM Technique | D4: Cost | E4: Reliability | F4: Ease of implementation | G4: Compatibility | H4: Real time information | I4: Efficiency | J4: Risk Reduction | K4: Sustainability
A5: ='1. Decision Matrix'!A5 -> 1 | B5: ='1. Decision Matrix'!B5 -> IoT Sensors | C5: ='1. Decision Matrix'!C5 -> Procurement Management | D5: ='1. Decision Matrix'!D5/SQRT(SUMSQ('1. Decision Matrix'!D$5:D$29)) -> 0.19625938 | E5: ='1. Decision Matrix'!E5/SQRT(SUMSQ('1. Decision Matrix'!E$5:E$29)) -> 0.1969821 | F5: ='1. Decision Matrix'!F5/SQRT(SUMSQ('1. Decision Matrix'!F$5:F$29)) -> 0.20292683 | G5: ='1. Decision Matrix'!G5/SQRT(SUMSQ('1. Decision Matrix'!G$5:G$29)) -> 0.19678017 | H5: ='1. Decision Matrix'!H5/SQRT(SUMSQ('1. Decision Matrix'!H$5:H$29)) -> 0.19015541 | I5: ='1. Decision Matrix'!I5/SQRT(SUMSQ('1. Decision Matrix'!I$5:I$29)) -> 0.19458871 | J5: ='1. Decision Matrix'!J5/SQRT(SUMSQ('1. Decision Matrix'!J$5:J$29)) -> 0.19851398 | K5: ='1. Decision Matrix'!K5/SQRT(SUMSQ('1. Decision Matrix'!K$5:K$29)) -> 0.19284348
A6: ='1. Decision Matrix'!A6 -> 2 | B6: ='1. Decision Matrix'!B6 -> IoT Sensors | C6: ='1. Decision Matrix'!C6 -> Inventory Management | D6: ='1. Decision Matrix'!D6/SQRT(SUMSQ('1. Decision Matrix'!D$5:D$29)) -> 0.19727627 | E6: ='1. Decision Matrix'!E6/SQRT(SUMSQ('1. Decision Matrix'!E$5:E$29)) -> 0.19998619 | F6: ='1. Decision Matrix'!F6/SQRT(SUMSQ('1. Decision Matrix'!F$5:F$29)) -> 0.2020309 | G6: ='1. Decision Matrix'!G6/SQRT(SUMSQ('1. Decision Matrix'!G$5:G$29)) -> 0.20024004 | H6: ='1. Decision Matrix'!H6/SQRT(SUMSQ('1. Decision Matrix'!H$5:H$29)) -> 0.19993969 | I6: ='1. Decision Matrix'!I6/SQRT(SUMSQ('1. Decision Matrix'!I$5:I$29)) -> 0.19922178 | J6: ='1. Decision Matrix'!J6/SQRT(SUMSQ('1. Decision Matrix'!J$5:J$29)) -> 0.20199668 | K6: ='1. Decision Matrix'!K6/SQRT(SUMSQ('1. Decision Matrix'!K$5:K$29)) -> 0.19842692
A7: ='1. Decision Matrix'!A7 -> 3 | B7: ='1. Decision Matrix'!B7 -> IoT Sensors | C7: ='1. Decision Matrix'!C7 -> Logistics Management | D7: ='1. Decision Matrix'!D7/SQRT(SUMSQ('1. Decision Matrix'!D$5:D$29)) -> 0.19371716 | E7: ='1. Decision Matrix'!E7/SQRT(SUMSQ('1. Decision Matrix'!E$5:E$29)) -> 0.20041534 | F7: ='1. Decision Matrix'!F7/SQRT(SUMSQ('1. Decision Matrix'!F$5:F$29)) -> 0.20247887 | G7: ='1. Decision Matrix'!G7/SQRT(SUMSQ('1. Decision Matrix'!G$5:G$29)) -> 0.19678017 | H7: ='1. Decision Matrix'!H7/SQRT(SUMSQ('1. Decision Matrix'!H$5:H$29)) -> 0.20164131 | I7: ='1. Decision Matrix'!I7/SQRT(SUMSQ('1. Decision Matrix'!I$5:I$29)) -> 0.19795822 | J7: ='1. Decision Matrix'!J7/SQRT(SUMSQ('1. Decision Matrix'!J$5:J$29)) -> 0.201126 | K7: ='1. Decision Matrix'!K7/SQRT(SUMSQ('1. Decision Matrix'!K$5:K$29)) -> 0.19456146
A8: ='1. Decision Matrix'!A8 -> 4 | B8: ='1. Decision Matrix'!B8 -> IoT Sensors | C8: ='1. Decision Matrix'!C8 -> Supplier Management | D8: ='1. Decision Matrix'!D8/SQRT(SUMSQ('1. Decision Matrix'!D$5:D$29)) -> 0.19676783 | E8: ='1. Decision Matrix'!E8/SQRT(SUMSQ('1. Decision Matrix'!E$5:E$29)) -> 0.19826957 | F8: ='1. Decision Matrix'!F8/SQRT(SUMSQ('1. Decision Matrix'!F$5:F$29)) -> 0.20427071 | G8: ='1. Decision Matrix'!G8/SQRT(SUMSQ('1. Decision Matrix'!G$5:G$29)) -> 0.19721265 | H8: ='1. Decision Matrix'!H8/SQRT(SUMSQ('1. Decision Matrix'!H$5:H$29)) -> 0.19568566 | I8: ='1. Decision Matrix'!I8/SQRT(SUMSQ('1. Decision Matrix'!I$5:I$29)) -> 0.1950099 | J8: ='1. Decision Matrix'!J8/SQRT(SUMSQ('1. Decision Matrix'!J$5:J$29)) -> 0.19894931 | K8: ='1. Decision Matrix'!K8/SQRT(SUMSQ('1. Decision Matrix'!K$5:K$29)) -> 0.19542045
A9: ='1. Decision Matrix'!A9 -> 5 | B9: ='1. Decision Matrix'!B9 -> IoT Sensors | C9: ='1. Decision Matrix'!C9 -> Just-in-Time | D9: ='1. Decision Matrix'!D9/SQRT(SUMSQ('1. Decision Matrix'!D$5:D$29)) -> 0.19931005 | E9: ='1. Decision Matrix'!E9/SQRT(SUMSQ('1. Decision Matrix'!E$5:E$29)) -> 0.19784041 | F9: ='1. Decision Matrix'!F9/SQRT(SUMSQ('1. Decision Matrix'!F$5:F$29)) -> 0.19665536 | G9: ='1. Decision Matrix'!G9/SQRT(SUMSQ('1. Decision Matrix'!G$5:G$29)) -> 0.19418526 | H9: ='1. Decision Matrix'!H9/SQRT(SUMSQ('1. Decision Matrix'!H$5:H$29)) -> 0.20291752 | I9: ='1. Decision Matrix'!I9/SQRT(SUMSQ('1. Decision Matrix'!I$5:I$29)) -> 0.19543109 | J9: ='1. Decision Matrix'!J9/SQRT(SUMSQ('1. Decision Matrix'!J$5:J$29)) -> 0.20025533 | K9: ='1. Decision Matrix'!K9/SQRT(SUMSQ('1. Decision Matrix'!K$5:K$29)) -> 0.19971541
A10: ='1. Decision Matrix'!A10 -> 6 | B10: ='1. Decision Matrix'!B10 -> RFID | C10: ='1. Decision Matrix'!C10 -> Procurement Management | D10: ='1. Decision Matrix'!D10/SQRT(SUMSQ('1. Decision Matrix'!D$5:D$29)) -> 0.21100426 | E10: ='1. Decision Matrix'!E10/SQRT(SUMSQ('1. Decision Matrix'!E$5:E$29)) -> 0.1969821 | F10: ='1. Decision Matrix'!F10/SQRT(SUMSQ('1. Decision Matrix'!F$5:F$29)) -> 0.20606256 | G10: ='1. Decision Matrix'!G10/SQRT(SUMSQ('1. Decision Matrix'!G$5:G$29)) -> 0.19894259 | H10: ='1. Decision Matrix'!H10/SQRT(SUMSQ('1. Decision Matrix'!H$5:H$29)) -> 0.19015541 | I10: ='1. Decision Matrix'!I10/SQRT(SUMSQ('1. Decision Matrix'!I$5:I$29)) -> 0.19753703 | J10: ='1. Decision Matrix'!J10/SQRT(SUMSQ('1. Decision Matrix'!J$5:J$29)) -> 0.19938465 | K10: ='1. Decision Matrix'!K10/SQRT(SUMSQ('1. Decision Matrix'!K$5:K$29)) -> 0.19713843
A11: ='1. Decision Matrix'!A11 -> 7 | B11: ='1. Decision Matrix'!B11 -> RFID | C11: ='1. Decision Matrix'!C11 -> Inventory Management | D11: ='1. Decision Matrix'!D11/SQRT(SUMSQ('1. Decision Matrix'!D$5:D$29)) -> 0.21202115 | E11: ='1. Decision Matrix'!E11/SQRT(SUMSQ('1. Decision Matrix'!E$5:E$29)) -> 0.19998619 | F11: ='1. Decision Matrix'!F11/SQRT(SUMSQ('1. Decision Matrix'!F$5:F$29)) -> 0.20516664 | G11: ='1. Decision Matrix'!G11/SQRT(SUMSQ('1. Decision Matrix'!G$5:G$29)) -> 0.20240246 | H11: ='1. Decision Matrix'!H11/SQRT(SUMSQ('1. Decision Matrix'!H$5:H$29)) -> 0.19993969 | I11: ='1. Decision Matrix'!I11/SQRT(SUMSQ('1. Decision Matrix'!I$5:I$29)) -> 0.20217009 | J11: ='1. Decision Matrix'!J11/SQRT(SUMSQ('1. Decision Matrix'!J$5:J$29)) -> 0.20286735 | K11: ='1. Decision Matrix'!K11/SQRT(SUMSQ('1. Decision Matrix'!K$5:K$29)) -> 0.20272187
A12: ='1. Decision Matrix'!A12 -> 8 | B12: ='1. Decision Matrix'!B12 -> RFID | C12: ='1. Decision Matrix'!C12 -> Logistics Management | D12: ='1. Decision Matrix'!D12/SQRT(SUMSQ('1. Decision Matrix'!D$5:D$29)) -> 0.20846204 | E12: ='1. Decision Matrix'!E12/SQRT(SUMSQ('1. Decision Matrix'!E$5:E$29)) -> 0.20041534 | F12: ='1. Decision Matrix'!F12/SQRT(SUMSQ('1. Decision Matrix'!F$5:F$29)) -> 0.2056146 | G12: ='1. Decision Matrix'!G12/SQRT(SUMSQ('1. Decision Matrix'!G$5:G$29)) -> 0.19894259 | H12: ='1. Decision Matrix'!H12/SQRT(SUMSQ('1. Decision Matrix'!H$5:H$29)) -> 0.20164131 | I12: ='1. Decision Matrix'!I12/SQRT(SUMSQ('1. Decision Matrix'!I$5:I$29)) -> 0.20090653 | J12: ='1. Decision Matrix'!J12/SQRT(SUMSQ('1. Decision Matrix'!J$5:J$29)) -> 0.20199668 | K12: ='1. Decision Matrix'!K12/SQRT(SUMSQ('1. Decision Matrix'!K$5:K$29)) -> 0.19885641
A13: ='1. Decision Matrix'!A13 -> 9 | B13: ='1. Decision Matrix'!B13 -> RFID | C13: ='1. Decision Matrix'!C13 -> Supplier Management | D13: ='1. Decision Matrix'!D13/SQRT(SUMSQ('1. Decision Matrix'!D$5:D$29)) -> 0.2115127 | E13: ='1. Decision Matrix'!E13/SQRT(SUMSQ('1. Decision Matrix'!E$5:E$29)) -> 0.19826957 | F13: ='1. Decision Matrix'!F13/SQRT(SUMSQ('1. Decision Matrix'!F$5:F$29)) -> 0.20740645 | G13: ='1. Decision Matrix'!G13/SQRT(SUMSQ('1. Decision Matrix'!G$5:G$29)) -> 0.19937507 | H13: ='1. Decision Matrix'!H13/SQRT(SUMSQ('1. Decision Matrix'!H$5:H$29)) -> 0.19568566 | I13: ='1. Decision Matrix'!I13/SQRT(SUMSQ('1. Decision Matrix'!I$5:I$29)) -> 0.19795822 | J13: ='1. Decision Matrix'!J13/SQRT(SUMSQ('1. Decision Matrix'!J$5:J$29)) -> 0.19981999 | K13: ='1. Decision Matrix'!K13/SQRT(SUMSQ('1. Decision Matrix'!K$5:K$29)) -> 0.19971541
A14: ='1. Decision Matrix'!A14 -> 10 | B14: ='1. Decision Matrix'!B14 -> RFID | C14: ='1. Decision Matrix'!C14 -> Just-in-Time | D14: ='1. Decision Matrix'!D14/SQRT(SUMSQ('1. Decision Matrix'!D$5:D$29)) -> 0.21405492 | E14: ='1. Decision Matrix'!E14/SQRT(SUMSQ('1. Decision Matrix'!E$5:E$29)) -> 0.19784041 | F14: ='1. Decision Matrix'!F14/SQRT(SUMSQ('1. Decision Matrix'!F$5:F$29)) -> 0.19979109 | G14: ='1. Decision Matrix'!G14/SQRT(SUMSQ('1. Decision Matrix'!G$5:G$29)) -> 0.19634768 | H14: ='1. Decision Matrix'!H14/SQRT(SUMSQ('1. Decision Matrix'!H$5:H$29)) -> 0.20291752 | I14: ='1. Decision Matrix'!I14/SQRT(SUMSQ('1. Decision Matrix'!I$5:I$29)) -> 0.1983794 | J14: ='1. Decision Matrix'!J14/SQRT(SUMSQ('1. Decision Matrix'!J$5:J$29)) -> 0.201126 | K14: ='1. Decision Matrix'!K14/SQRT(SUMSQ('1. Decision Matrix'!K$5:K$29)) -> 0.20401036
A15: ='1. Decision Matrix'!A15 -> 11 | B15: ='1. Decision Matrix'!B15 -> GPS | C15: ='1. Decision Matrix'!C15 -> Procurement Management | D15: ='1. Decision Matrix'!D15/SQRT(SUMSQ('1. Decision Matrix'!D$5:D$29)) -> 0.20744515 | E15: ='1. Decision Matrix'!E15/SQRT(SUMSQ('1. Decision Matrix'!E$5:E$29)) -> 0.20213196 | F15: ='1. Decision Matrix'!F15/SQRT(SUMSQ('1. Decision Matrix'!F$5:F$29)) -> 0.20740645 | G15: ='1. Decision Matrix'!G15/SQRT(SUMSQ('1. Decision Matrix'!G$5:G$29)) -> 0.19894259 | H15: ='1. Decision Matrix'!H15/SQRT(SUMSQ('1. Decision Matrix'!H$5:H$29)) -> 0.19313323 | I15: ='1. Decision Matrix'!I15/SQRT(SUMSQ('1. Decision Matrix'!I$5:I$29)) -> 0.19880059 | J15: ='1. Decision Matrix'!J15/SQRT(SUMSQ('1. Decision Matrix'!J$5:J$29)) -> 0.19720796 | K15: ='1. Decision Matrix'!K15/SQRT(SUMSQ('1. Decision Matrix'!K$5:K$29)) -> 0.19713843
A16: ='1. Decision Matrix'!A16 -> 12 | B16: ='1. Decision Matrix'!B16 -> GPS | C16: ='1. Decision Matrix'!C16 -> Inventory Management | D16: ='1. Decision Matrix'!D16/SQRT(SUMSQ('1. Decision Matrix'!D$5:D$29)) -> 0.20846204 | E16: ='1. Decision Matrix'!E16/SQRT(SUMSQ('1. Decision Matrix'!E$5:E$29)) -> 0.20513605 | F16: ='1. Decision Matrix'!F16/SQRT(SUMSQ('1. Decision Matrix'!F$5:F$29)) -> 0.20651053 | G16: ='1. Decision Matrix'!G16/SQRT(SUMSQ('1. Decision Matrix'!G$5:G$29)) -> 0.20240246 | H16: ='1. Decision Matrix'!H16/SQRT(SUMSQ('1. Decision Matrix'!H$5:H$29)) -> 0.20291752 | I16: ='1. Decision Matrix'!I16/SQRT(SUMSQ('1. Decision Matrix'!I$5:I$29)) -> 0.20343366 | J16: ='1. Decision Matrix'!J16/SQRT(SUMSQ('1. Decision Matrix'!J$5:J$29)) -> 0.20069067 | K16: ='1. Decision Matrix'!K16/SQRT(SUMSQ('1. Decision Matrix'!K$5:K$29)) -> 0.20272187
... A29: ='1. Decision Matrix'!A29 -> 25 | B29: ='1. Decision Matrix'!B29 -> Cloud computing | C29: ='1. Decision Matrix'!C29 -> Just-in-Time | D29: ='1. Decision Matrix'!D29/SQRT(SUMSQ('1. Decision Matrix'!D$5:D$29)) -> 0.19320872 | E29: ='1. Decision Matrix'!E29/SQRT(SUMSQ('1. Decision Matrix'!E$5:E$29)) -> 0.19826957 | F29: ='1. Decision Matrix'!F29/SQRT(SUMSQ('1. Decision Matrix'!F$5:F$29)) -> 0.19351962 | G29: ='1. Decision Matrix'!G29/SQRT(SUMSQ('1. Decision Matrix'!G$5:G$29)) -> 0.19894259 | H29: ='1. Decision Matrix'!H29/SQRT(SUMSQ('1. Decision Matrix'!H$5:H$29)) -> 0.20674615 | I29: ='1. Decision Matrix'!I29/SQRT(SUMSQ('1. Decision Matrix'!I$5:I$29)) -> 0.19922178 | J29: ='1. Decision Matrix'!J29/SQRT(SUMSQ('1. Decision Matrix'!J$5:J$29)) -> 0.19938465 | K29: ='1. Decision Matrix'!K29/SQRT(SUMSQ('1. Decision Matrix'!K$5:K$29)) -> 0.20358087

Sheet 3. Weighted Normalized
A1: TOPSIS Step 2 — Weighted Normalized Matrix
A2: v_ij = w_j × r_ij, using the criteria weights on the 'Weights' sheet.
A4: No. | B4: IoT Tool | C4: SCM Technique | D4: Cost | E4: Reliability | F4: Ease of implementation | G4: Compatibility | H4: Real time information | I4: Efficiency | J4: Risk Reduction | K4: Sustainability
A5: ='2. Normalized Matrix'!A5 -> 1 | B5: ='2. Normalized Matrix'!B5 -> IoT Sensors | C5: ='2. Normalized Matrix'!C5 -> Procurement Management | D5: ='2. Normalized Matrix'!D5*Weights!$B$4 -> 0.02120469 | E5: ='2. Normalized Matrix'!E5*Weights!$B$5 -> 0.025236064 | F5: ='2. Normalized Matrix'!F5*Weights!$B$6 -> 0.024893042 | G5: ='2. Normalized Matrix'!G5*Weights!$B$7 -> 0.025015437 | H5: ='2. Normalized Matrix'!H5*Weights!$B$8 -> 0.024570584 | I5: ='2. Normalized Matrix'!I5*Weights!$B$9 -> 0.025400209 | J5: ='2. Normalized Matrix'!J5*Weights!$B$10 -> 0.025072118 | K5: ='2. Normalized Matrix'!K5*Weights!$B$11 -> 0.024684644
A6: ='2. Normalized Matrix'!A6 -> 2 | B6: ='2. Normalized Matrix'!B6 -> IoT Sensors | C6: ='2. Normalized Matrix'!C6 -> Inventory Management | D6: ='2. Normalized Matrix'!D6*Weights!$B$4 -> 0.021314558 | E6: ='2. Normalized Matrix'!E6*Weights!$B$5 -> 0.025620928 | F6: ='2. Normalized Matrix'!F6*Weights!$B$6 -> 0.024783139 | G6: ='2. Normalized Matrix'!G6*Weights!$B$7 -> 0.025455268 | H6: ='2. Normalized Matrix'!H6*Weights!$B$8 -> 0.025834842 | I6: ='2. Normalized Matrix'!I6*Weights!$B$9 -> 0.026004976 | J6: ='2. Normalized Matrix'!J6*Weights!$B$10 -> 0.025511979 | K6: ='2. Normalized Matrix'!K6*Weights!$B$11 -> 0.025399344
A7: ='2. Normalized Matrix'!A7 -> 3 | B7: ='2. Normalized Matrix'!B7 -> IoT Sensors | C7: ='2. Normalized Matrix'!C7 -> Logistics Management | D7: ='2. Normalized Matrix'!D7*Weights!$B$4 -> 0.020930017 | E7: ='2. Normalized Matrix'!E7*Weights!$B$5 -> 0.025675908 | F7: ='2. Normalized Matrix'!F7*Weights!$B$6 -> 0.02483809 | G7: ='2. Normalized Matrix'!G7*Weights!$B$7 -> 0.025015437 | H7: ='2. Normalized Matrix'!H7*Weights!$B$8 -> 0.026054713 | I7: ='2. Normalized Matrix'!I7*Weights!$B$9 -> 0.02584004 | J7: ='2. Normalized Matrix'!J7*Weights!$B$10 -> 0.025402014 | K7: ='2. Normalized Matrix'!K7*Weights!$B$11 -> 0.024904552
A8: ='2. Normalized Matrix'!A8 -> 4 | B8: ='2. Normalized Matrix'!B8 -> IoT Sensors | C8: ='2. Normalized Matrix'!C8 -> Supplier Management | D8: ='2. Normalized Matrix'!D8*Weights!$B$4 -> 0.021259624 | E8: ='2. Normalized Matrix'!E8*Weights!$B$5 -> 0.025401006 | F8: ='2. Normalized Matrix'!F8*Weights!$B$6 -> 0.025057897 | G8: ='2. Normalized Matrix'!G8*Weights!$B$7 -> 0.025070415 | H8: ='2. Normalized Matrix'!H8*Weights!$B$8 -> 0.025285165 | I8: ='2. Normalized Matrix'!I8*Weights!$B$9 -> 0.025455188 | J8: ='2. Normalized Matrix'!J8*Weights!$B$10 -> 0.0251271 | K8: ='2. Normalized Matrix'!K8*Weights!$B$11 -> 0.025014505
A9: ='2. Normalized Matrix'!A9 -> 5 | B9: ='2. Normalized Matrix'!B9 -> IoT Sensors | C9: ='2. Normalized Matrix'!C9 -> Just-in-Time | D9: ='2. Normalized Matrix'!D9*Weights!$B$4 -> 0.021534296 | E9: ='2. Normalized Matrix'!E9*Weights!$B$5 -> 0.025346025 | F9: ='2. Normalized Matrix'!F9*Weights!$B$6 -> 0.024123721 | G9: ='2. Normalized Matrix'!G9*Weights!$B$7 -> 0.024685563 | H9: ='2. Normalized Matrix'!H9*Weights!$B$8 -> 0.026219617 | I9: ='2. Normalized Matrix'!I9*Weights!$B$9 -> 0.025510167 | J9: ='2. Normalized Matrix'!J9*Weights!$B$10 -> 0.025292049 | K9: ='2. Normalized Matrix'!K9*Weights!$B$11 -> 0.025564275
A10: ='2. Normalized Matrix'!A10 -> 6 | B10: ='2. Normalized Matrix'!B10 -> RFID | C10: ='2. Normalized Matrix'!C10 -> Procurement Management | D10: ='2. Normalized Matrix'!D10*Weights!$B$4 -> 0.022797788 | E10: ='2. Normalized Matrix'!E10*Weights!$B$5 -> 0.025236064 | F10: ='2. Normalized Matrix'!F10*Weights!$B$6 -> 0.025277703 | G10: ='2. Normalized Matrix'!G10*Weights!$B$7 -> 0.025290331 | H10: ='2. Normalized Matrix'!H10*Weights!$B$8 -> 0.024570584 | I10: ='2. Normalized Matrix'!I10*Weights!$B$9 -> 0.025785061 | J10: ='2. Normalized Matrix'!J10*Weights!$B$10 -> 0.025182083 | K10: ='2. Normalized Matrix'!K10*Weights!$B$11 -> 0.025234413
A11: ='2. Normalized Matrix'!A11 -> 7 | B11: ='2. Normalized Matrix'!B11 -> RFID | C11: ='2. Normalized Matrix'!C11 -> Inventory Management | D11: ='2. Normalized Matrix'!D11*Weights!$B$4 -> 0.022907657 | E11: ='2. Normalized Matrix'!E11*Weights!$B$5 -> 0.025620928 | F11: ='2. Normalized Matrix'!F11*Weights!$B$6 -> 0.0251678 | G11: ='2. Normalized Matrix'!G11*Weights!$B$7 -> 0.025730163 | H11: ='2. Normalized Matrix'!H11*Weights!$B$8 -> 0.025834842 | I11: ='2. Normalized Matrix'!I11*Weights!$B$9 -> 0.026389828 | J11: ='2. Normalized Matrix'!J11*Weights!$B$10 -> 0.025621945 | K11: ='2. Normalized Matrix'!K11*Weights!$B$11 -> 0.025949113
A12: ='2. Normalized Matrix'!A12 -> 8 | B12: ='2. Normalized Matrix'!B12 -> RFID | C12: ='2. Normalized Matrix'!C12 -> Logistics Management | D12: ='2. Normalized Matrix'!D12*Weights!$B$4 -> 0.022523116 | E12: ='2. Normalized Matrix'!E12*Weights!$B$5 -> 0.025675908 | F12: ='2. Normalized Matrix'!F12*Weights!$B$6 -> 0.025222751 | G12: ='2. Normalized Matrix'!G12*Weights!$B$7 -> 0.025290331 | H12: ='2. Normalized Matrix'!H12*Weights!$B$8 -> 0.026054713 | I12: ='2. Normalized Matrix'!I12*Weights!$B$9 -> 0.026224892 | J12: ='2. Normalized Matrix'!J12*Weights!$B$10 -> 0.025511979 | K12: ='2. Normalized Matrix'!K12*Weights!$B$11 -> 0.025454321
A13: ='2. Normalized Matrix'!A13 -> 9 | B13: ='2. Normalized Matrix'!B13 -> RFID | C13: ='2. Normalized Matrix'!C13 -> Supplier Management | D13: ='2. Normalized Matrix'!D13*Weights!$B$4 -> 0.022852722 | E13: ='2. Normalized Matrix'!E13*Weights!$B$5 -> 0.025401006 | F13: ='2. Normalized Matrix'!F13*Weights!$B$6 -> 0.025442557 | G13: ='2. Normalized Matrix'!G13*Weights!$B$7 -> 0.02534531 | H13: ='2. Normalized Matrix'!H13*Weights!$B$8 -> 0.025285165 | I13: ='2. Normalized Matrix'!I13*Weights!$B$9 -> 0.02584004 | J13: ='2. Normalized Matrix'!J13*Weights!$B$10 -> 0.025237066 | K13: ='2. Normalized Matrix'!K13*Weights!$B$11 -> 0.025564275
A14: ='2. Normalized Matrix'!A14 -> 10 | B14: ='2. Normalized Matrix'!B14 -> RFID | C14: ='2. Normalized Matrix'!C14 -> Just-in-Time | D14: ='2. Normalized Matrix'!D14*Weights!$B$4 -> 0.023127395 | E14: ='2. Normalized Matrix'!E14*Weights!$B$5 -> 0.025346025 | F14: ='2. Normalized Matrix'!F14*Weights!$B$6 -> 0.024508381 | G14: ='2. Normalized Matrix'!G14*Weights!$B$7 -> 0.024960458 | H14: ='2. Normalized Matrix'!H14*Weights!$B$8 -> 0.026219617 | I14: ='2. Normalized Matrix'!I14*Weights!$B$9 -> 0.025895019 | J14: ='2. Normalized Matrix'!J14*Weights!$B$10 -> 0.025402014 | K14: ='2. Normalized Matrix'!K14*Weights!$B$11 -> 0.026114044
A15: ='2. Normalized Matrix'!A15 -> 11 | B15: ='2. Normalized Matrix'!B15 -> GPS | C15: ='2. Normalized Matrix'!C15 -> Procurement Management | D15: ='2. Normalized Matrix'!D15*Weights!$B$4 -> 0.022413247 | E15: ='2. Normalized Matrix'!E15*Weights!$B$5 -> 0.02589583 | F15: ='2. Normalized Matrix'!F15*Weights!$B$6 -> 0.025442557 | G15: ='2. Normalized Matrix'!G15*Weights!$B$7 -> 0.025290331 | H15: ='2. Normalized Matrix'!H15*Weights!$B$8 -> 0.024955358 | I15: ='2. Normalized Matrix'!I15*Weights!$B$9 -> 0.025949998 | J15: ='2. Normalized Matrix'!J15*Weights!$B$10 -> 0.02490717 | K15: ='2. Normalized Matrix'!K15*Weights!$B$11 -> 0.025234413
A16: ='2. Normalized Matrix'!A16 -> 12 | B16: ='2. Normalized Matrix'!B16 -> GPS | C16: ='2. Normalized Matrix'!C16 -> Inventory Management | D16: ='2. Normalized Matrix'!D16*Weights!$B$4 -> 0.022523116 | E16: ='2. Normalized Matrix'!E16*Weights!$B$5 -> 0.026280694 | F16: ='2. Normalized Matrix'!F16*Weights!$B$6 -> 0.025332654 | G16: ='2. Normalized Matrix'!G16*Weights!$B$7 -> 0.025730163 | H16: ='2. Normalized Matrix'!H16*Weights!$B$8 -> 0.026219617 | I16: ='2. Normalized Matrix'!I16*Weights!$B$9 -> 0.026554764 | J16: ='2. Normalized Matrix'!J16*Weights!$B$10 -> 0.025347031 | K16: ='2. Normalized Matrix'!K16*Weights!$B$11 -> 0.025949113
... A29: ='2. Normalized Matrix'!A29 -> 25 | B29: ='2. Normalized Matrix'!B29 -> Cloud computing | C29: ='2. Normalized Matrix'!C29 -> Just-in-Time | D29: ='2. Normalized Matrix'!D29*Weights!$B$4 -> 0.020875083 | E29: ='2. Normalized Matrix'!E29*Weights!$B$5 -> 0.025401006 | F29: ='2. Normalized Matrix'!F29*Weights!$B$6 -> 0.02373906 | G29: ='2. Normalized Matrix'!G29*Weights!$B$7 -> 0.025290331 | H29: ='2. Normalized Matrix'!H29*Weights!$B$8 -> 0.026714326 | I29: ='2. Normalized Matrix'!I29*Weights!$B$9 -> 0.026004976 | J29: ='2. Normalized Matrix'!J29*Weights!$B$10 -> 0.025182083 | K29: ='2. Normalized Matrix'!K29*Weights!$B$11 -> 0.026059067

Sheet 4. Ideal Solutions
A1: TOPSIS Step 3 — Positive Ideal (A+) and Negative Ideal (A-) Solutions
A2: Benefit criteria: A+ = column MAX, A- = column MIN. Cost criteria: A+ = column MIN, A- = column MAX.
A4: Solution | B4: Cost | C4: Reliability | D4: Ease of implementation | E4: Compatibility | F4: Real time information | G4: Efficiency | H4: Risk Reduction | I4: Sustainability
A5: A+ (Positive Ideal) | B5: =MIN('3. Weighted Normalized'!D$5:D$29) -> 0.020270804 | C5: =MAX('3. Weighted Normalized'!E$5:E$29) -> 0.026335675 | D5: =MAX('3. Weighted Normalized'!F$5:F$29) -> 0.025607412 | E5: =MAX('3. Weighted Normalized'!G$5:G$29) -> 0.026169995 | F5: =MAX('3. Weighted Normalized'!H$5:H$29) -> 0.026714326 | G5: =MAX('3. Weighted Normalized'!I$5:I$29) -> 0.026884637 | H5: =MAX('3. Weighted Normalized'!J$5:J$29) -> 0.025621945 | I5: =MAX('3. Weighted Normalized'!K$5:K$29) -> 0.026388929
A6: A- (Negative Ideal) | B6: =MAX('3. Weighted Normalized'!D$5:D$29) -> 0.023127395 | C6: =MIN('3. Weighted Normalized'!E$5:E$29) -> 0.025236064 | D6: =MIN('3. Weighted Normalized'!F$5:F$29) -> 0.022475175 | E6: =MIN('3. Weighted Normalized'!G$5:G$29) -> 0.024685563 | F6: =MIN('3. Weighted Normalized'!H$5:H$29) -> 0.024570584 | G6: =MIN('3. Weighted Normalized'!I$5:I$29) -> 0.025400209 | H6: =MIN('3. Weighted Normalized'!J$5:J$29) -> 0.02490717 | I6: =MIN('3. Weighted Normalized'!K$5:K$29) -> 0.024684644

Sheet 5. Separation Measures
A1: TOPSIS Step 4 — Separation Measures from Ideal Solutions
A2: S+ = Euclidean distance to A+ (positive ideal). S- = Euclidean distance to A- (negative ideal).
A4: No. | B4: IoT Tool | C4: SCM Technique | D4: S+ (distance to ideal best) | E4: S- (distance to ideal worst)
A5: ='3. Weighted Normalized'!A5 -> 1 | B5: ='3. Weighted Normalized'!B5 -> IoT Sensors | C5: ='3. Weighted Normalized'!C5 -> Procurement Management | D5: =SQRT(('3. Weighted Normalized'!D5-'4. Ideal Solutions'!$B$5)^2+('3. Weighted Normalized'!E5-'4. Ideal Solutions'!$C$5)^2+('3. Weighted Normalized'!F5-'4. Ideal Solutions'!$D$5)^2+('3. Weighted Normalized'!G5-'4. Ideal Solutions'!$E$5)^2+('3. Weighted Normalized'!H5-'4. Ideal Solutions'!$F$5)^2+('3. Weighted Normalized'!I5-'4. Ideal Solutions'!$G$5)^2+('3. Weighted Normalized'!J5-'4. Ideal Solutions'!$H$5)^2+('3. Weighted Normalized'!K5-'4. Ideal Solutions'!$I$5)^2) -> 0.0037323812 | E5: =SQRT(('3. Weighted Normalized'!D5-'4. Ideal Solutions'!$B$6)^2+('3. Weighted Normalized'!E5-'4. Ideal Solutions'!$C$6)^2+('3. Weighted Normalized'!F5-'4. Ideal Solutions'!$D$6)^2+('3. Weighted Normalized'!G5-'4. Ideal Solutions'!$E$6)^2+('3. Weighted Normalized'!H5-'4. Ideal Solutions'!$F$6)^2+('3. Weighted Normalized'!I5-'4. Ideal Solutions'!$G$6)^2+('3. Weighted Normalized'!J5-'4. Ideal Solutions'!$H$6)^2+('3. Weighted Normalized'!K5-'4. Ideal Solutions'!$I$6)^2) -> 0.0031110932
A6: ='3. Weighted Normalized'!A6 -> 2 | B6: ='3. Weighted Normalized'!B6 -> IoT Sensors | C6: ='3. Weighted Normalized'!C6 -> Inventory Management | D6: =SQRT(('3. Weighted Normalized'!D6-'4. Ideal Solutions'!$B$5)^2+('3. Weighted Normalized'!E6-'4. Ideal Solutions'!$C$5)^2+('3. Weighted Normalized'!F6-'4. Ideal Solutions'!$D$5)^2+('3. Weighted Normalized'!G6-'4. Ideal Solutions'!$E$5)^2+('3. Weighted Normalized'!H6-'4. Ideal Solutions'!$F$5)^2+('3. Weighted Normalized'!I6-'4. Ideal Solutions'!$G$5)^2+('3. Weighted Normalized'!J6-'4. Ideal Solutions'!$H$5)^2+('3. Weighted Normalized'!K6-'4. Ideal Solutions'!$I$5)^2) -> 0.0023085086 | E6: =SQRT(('3. Weighted Normalized'!D6-'4. Ideal Solutions'!$B$6)^2+('3. Weighted Normalized'!E6-'4. Ideal Solutions'!$C$6)^2+('3. Weighted Normalized'!F6-'4. Ideal Solutions'!$D$6)^2+('3. Weighted Normalized'!G6-'4. Ideal Solutions'!$E$6)^2+('3. Weighted Normalized'!H6-'4. Ideal Solutions'!$F$6)^2+('3. Weighted Normalized'!I6-'4. Ideal Solutions'!$G$6)^2+('3. Weighted Normalized'!J6-'4. Ideal Solutions'!$H$6)^2+('3. Weighted Normalized'!K6-'4. Ideal Solutions'!$I$6)^2) -> 0.0034920372
A7: ='3. Weighted Normalized'!A7 -> 3 | B7: ='3. Weighted Normalized'!B7 -> IoT Sensors | C7: ='3. Weighted Normalized'!C7 -> Logistics Management | D7: =SQRT(('3. Weighted Normalized'!D7-'4. Ideal Solutions'!$B$5)^2+('3. Weighted Normalized'!E7-'4. Ideal Solutions'!$C$5)^2+('3. Weighted Normalized'!F7-'4. Ideal Solutions'!$D$5)^2+('3. Weighted Normalized'!G7-'4. Ideal Solutions'!$E$5)^2+('3. Weighted Normalized'!H7-'4. Ideal Solutions'!$F$5)^2+('3. Weighted Normalized'!I7-'4. Ideal Solutions'!$G$5)^2+('3. Weighted Normalized'!J7-'4. Ideal Solutions'!$H$5)^2+('3. Weighted Normalized'!K7-'4. Ideal Solutions'!$I$5)^2) -> 0.0025637342 | E7: =SQRT(('3. Weighted Normalized'!D7-'4. Ideal Solutions'!$B$6)^2+('3. Weighted Normalized'!E7-'4. Ideal Solutions'!$C$6)^2+('3. Weighted Normalized'!F7-'4. Ideal Solutions'!$D$6)^2+('3. Weighted Normalized'!G7-'4. Ideal Solutions'!$E$6)^2+('3. Weighted Normalized'!H7-'4. Ideal Solutions'!$F$6)^2+('3. Weighted Normalized'!I7-'4. Ideal Solutions'!$G$6)^2+('3. Weighted Normalized'!J7-'4. Ideal Solutions'!$H$6)^2+('3. Weighted Normalized'!K7-'4. Ideal Solutions'!$I$6)^2) -> 0.0036610705
A8: ='3. Weighted Normalized'!A8 -> 4 | B8: ='3. Weighted Normalized'!B8 -> IoT Sensors | C8: ='3. Weighted Normalized'!C8 -> Supplier Management | D8: =SQRT(('3. Weighted Normalized'!D8-'4. Ideal Solutions'!$B$5)^2+('3. Weighted Normalized'!E8-'4. Ideal Solutions'!$C$5)^2+('3. Weighted Normalized'!F8-'4. Ideal Solutions'!$D$5)^2+('3. Weighted Normalized'!G8-'4. Ideal Solutions'!$E$5)^2+('3. Weighted Normalized'!H8-'4. Ideal Solutions'!$F$5)^2+('3. Weighted Normalized'!I8-'4. Ideal Solutions'!$G$5)^2+('3. Weighted Normalized'!J8-'4. Ideal Solutions'!$H$5)^2+('3. Weighted Normalized'!K8-'4. Ideal Solutions'!$I$5)^2) -> 0.0030955049 | E8: =SQRT(('3. Weighted Normalized'!D8-'4. Ideal Solutions'!$B$6)^2+('3. Weighted Normalized'!E8-'4. Ideal Solutions'!$C$6)^2+('3. Weighted Normalized'!F8-'4. Ideal Solutions'!$D$6)^2+('3. Weighted Normalized'!G8-'4. Ideal Solutions'!$E$6)^2+('3. Weighted Normalized'!H8-'4. Ideal Solutions'!$F$6)^2+('3. Weighted Normalized'!I8-'4. Ideal Solutions'!$G$6)^2+('3. Weighted Normalized'!J8-'4. Ideal Solutions'!$H$6)^2+('3. Weighted Normalized'!K8-'4. Ideal Solutions'!$I$6)^2) -> 0.003317403
A9: ='3. Weighted Normalized'!A9 -> 5 | B9: ='3. Weighted Normalized'!B9 -> IoT Sensors | C9: ='3. Weighted Normalized'!C9 -> Just-in-Time | D9: =SQRT(('3. Weighted Normalized'!D9-'4. Ideal Solutions'!$B$5)^2+('3. Weighted Normalized'!E9-'4. Ideal Solutions'!$C$5)^2+('3. Weighted Normalized'!F9-'4. Ideal Solutions'!$D$5)^2+('3. Weighted Normalized'!G9-'4. Ideal Solutions'!$E$5)^2+('3. Weighted Normalized'!H9-'4. Ideal Solutions'!$F$5)^2+('3. Weighted Normalized'!I9-'4. Ideal Solutions'!$G$5)^2+('3. Weighted Normalized'!J9-'4. Ideal Solutions'!$H$5)^2+('3. Weighted Normalized'!K9-'4. Ideal Solutions'!$I$5)^2) -> 0.003146981 | E9: =SQRT(('3. Weighted Normalized'!D9-'4. Ideal Solutions'!$B$6)^2+('3. Weighted Normalized'!E9-'4. Ideal Solutions'!$C$6)^2+('3. Weighted Normalized'!F9-'4. Ideal Solutions'!$D$6)^2+('3. Weighted Normalized'!G9-'4. Ideal Solutions'!$E$6)^2+('3. Weighted Normalized'!H9-'4. Ideal Solutions'!$F$6)^2+('3. Weighted Normalized'!I9-'4. Ideal Solutions'!$G$6)^2+('3. Weighted Normalized'!J9-'4. Ideal Solutions'!$H$6)^2+('3. Weighted Normalized'!K9-'4. Ideal Solutions'!$I$6)^2) -> 0.0029868108
A10: ='3. Weighted Normalized'!A10 -> 6 | B10: ='3. Weighted Normalized'!B10 -> RFID | C10: ='3. Weighted Normalized'!C10 -> Procurement Management | D10: =SQRT(('3. Weighted Normalized'!D10-'4. Ideal Solutions'!$B$5)^2+('3. Weighted Normalized'!E10-'4. Ideal Solutions'!$C$5)^2+('3. Weighted Normalized'!F10-'4. Ideal Solutions'!$D$5)^2+('3. Weighted Normalized'!G10-'4. Ideal Solutions'!$E$5)^2+('3. Weighted Normalized'!H10-'4. Ideal Solutions'!$F$5)^2+('3. Weighted Normalized'!I10-'4. Ideal Solutions'!$G$5)^2+('3. Weighted Normalized'!J10-'4. Ideal Solutions'!$H$5)^2+('3. Weighted Normalized'!K10-'4. Ideal Solutions'!$I$5)^2) -> 0.0039759766 | E10: =SQRT(('3. Weighted Normalized'!D10-'4. Ideal Solutions'!$B$6)^2+('3. Weighted Normalized'!E10-'4. Ideal Solutions'!$C$6)^2+('3. Weighted Normalized'!F10-'4. Ideal Solutions'!$D$6)^2+('3. Weighted Normalized'!G10-'4. Ideal Solutions'!$E$6)^2+('3. Weighted Normalized'!H10-'4. Ideal Solutions'!$F$6)^2+('3. Weighted Normalized'!I10-'4. Ideal Solutions'!$G$6)^2+('3. Weighted Normalized'!J10-'4. Ideal Solutions'!$H$6)^2+('3. Weighted Normalized'!K10-'4. Ideal Solutions'!$I$6)^2) -> 0.0029756483
A11: ='3. Weighted Normalized'!A11 -> 7 | B11: ='3. Weighted Normalized'!B11 -> RFID | C11: ='3. Weighted Normalized'!C11 -> Inventory Management | D11: =SQRT(('3. Weighted Normalized'!D11-'4. Ideal Solutions'!$B$5)^2+('3. Weighted Normalized'!E11-'4. Ideal Solutions'!$C$5)^2+('3. Weighted Normalized'!F11-'4. Ideal Solutions'!$D$5)^2+('3. Weighted Normalized'!G11-'4. Ideal Solutions'!$E$5)^2+('3. Weighted Normalized'!H11-'4. Ideal Solutions'!$F$5)^2+('3. Weighted Normalized'!I11-'4. Ideal Solutions'!$G$5)^2+('3. Weighted Normalized'!J11-'4. Ideal Solutions'!$H$5)^2+('3. Weighted Normalized'!K11-'4. Ideal Solutions'!$I$5)^2) -> 0.0030103707 | E11: =SQRT(('3. Weighted Normalized'!D11-'4. Ideal Solutions'!$B$6)^2+('3. Weighted Normalized'!E11-'4. Ideal Solutions'!$C$6)^2+('3. Weighted Normalized'!F11-'4. Ideal Solutions'!$D$6)^2+('3. Weighted Normalized'!G11-'4. Ideal Solutions'!$E$6)^2+('3. Weighted Normalized'!H11-'4. Ideal Solutions'!$F$6)^2+('3. Weighted Normalized'!I11-'4. Ideal Solutions'!$G$6)^2+('3. Weighted Normalized'!J11-'4. Ideal Solutions'!$H$6)^2+('3. Weighted Normalized'!K11-'4. Ideal Solutions'!$I$6)^2) -> 0.0036366612
A12: ='3. Weighted Normalized'!A12 -> 8 | B12: ='3. Weighted Normalized'!B12 -> RFID | C12: ='3. Weighted Normalized'!C12 -> Logistics Management | D12: =SQRT(('3. Weighted Normalized'!D12-'4. Ideal Solutions'!$B$5)^2+('3. Weighted Normalized'!E12-'4. Ideal Solutions'!$C$5)^2+('3. Weighted Normalized'!F12-'4. Ideal Solutions'!$D$5)^2+('3. Weighted Normalized'!G12-'4. Ideal Solutions'!$E$5)^2+('3. Weighted Normalized'!H12-'4. Ideal Solutions'!$F$5)^2+('3. Weighted Normalized'!I12-'4. Ideal Solutions'!$G$5)^2+('3. Weighted Normalized'!J12-'4. Ideal Solutions'!$H$5)^2+('3. Weighted Normalized'!K12-'4. Ideal Solutions'!$I$5)^2) -> 0.0028611028 | E12: =SQRT(('3. Weighted Normalized'!D12-'4. Ideal Solutions'!$B$6)^2+('3. Weighted Normalized'!E12-'4. Ideal Solutions'!$C$6)^2+('3. Weighted Normalized'!F12-'4. Ideal Solutions'!$D$6)^2+('3. Weighted Normalized'!G12-'4. Ideal Solutions'!$E$6)^2+('3. Weighted Normalized'!H12-'4. Ideal Solutions'!$F$6)^2+('3. Weighted Normalized'!I12-'4. Ideal Solutions'!$G$6)^2+('3. Weighted Normalized'!J12-'4. Ideal Solutions'!$H$6)^2+('3. Weighted Normalized'!K12-'4. Ideal Solutions'!$I$6)^2) -> 0.0035091986
A13: ='3. Weighted Normalized'!A13 -> 9 | B13: ='3. Weighted Normalized'!B13 -> RFID | C13: ='3. Weighted Normalized'!C13 -> Supplier Management | D13: =SQRT(('3. Weighted Normalized'!D13-'4. Ideal Solutions'!$B$5)^2+('3. Weighted Normalized'!E13-'4. Ideal Solutions'!$C$5)^2+('3. Weighted Normalized'!F13-'4. Ideal Solutions'!$D$5)^2+('3. Weighted Normalized'!G13-'4. Ideal Solutions'!$E$5)^2+('3. Weighted Normalized'!H13-'4. Ideal Solutions'!$F$5)^2+('3. Weighted Normalized'!I13-'4. Ideal Solutions'!$G$5)^2+('3. Weighted Normalized'!J13-'4. Ideal Solutions'!$H$5)^2+('3. Weighted Normalized'!K13-'4. Ideal Solutions'!$I$5)^2) -> 0.0034941468 | E13: =SQRT(('3. Weighted Normalized'!D13-'4. Ideal Solutions'!$B$6)^2+('3. Weighted Normalized'!E13-'4. Ideal Solutions'!$C$6)^2+('3. Weighted Normalized'!F13-'4. Ideal Solutions'!$D$6)^2+('3. Weighted Normalized'!G13-'4. Ideal Solutions'!$E$6)^2+('3. Weighted Normalized'!H13-'4. Ideal Solutions'!$F$6)^2+('3. Weighted Normalized'!I13-'4. Ideal Solutions'!$G$6)^2+('3. Weighted Normalized'!J13-'4. Ideal Solutions'!$H$6)^2+('3. Weighted Normalized'!K13-'4. Ideal Solutions'!$I$6)^2) -> 0.0033060452
A14: ='3. Weighted Normalized'!A14 -> 10 | B14: ='3. Weighted Normalized'!B14 -> RFID | C14: ='3. Weighted Normalized'!C14 -> Just-in-Time | D14: =SQRT(('3. Weighted Normalized'!D14-'4. Ideal Solutions'!$B$5)^2+('3. Weighted Normalized'!E14-'4. Ideal Solutions'!$C$5)^2+('3. Weighted Normalized'!F14-'4. Ideal Solutions'!$D$5)^2+('3. Weighted Normalized'!G14-'4. Ideal Solutions'!$E$5)^2+('3. Weighted Normalized'!H14-'4. Ideal Solutions'!$F$5)^2+('3. Weighted Normalized'!I14-'4. Ideal Solutions'!$G$5)^2+('3. Weighted Normalized'!J14-'4. Ideal Solutions'!$H$5)^2+('3. Weighted Normalized'!K14-'4. Ideal Solutions'!$I$5)^2) -> 0.0036274478 | E14: =SQRT(('3. Weighted Normalized'!D14-'4. Ideal Solutions'!$B$6)^2+('3. Weighted Normalized'!E14-'4. Ideal Solutions'!$C$6)^2+('3. Weighted Normalized'!F14-'4. Ideal Solutions'!$D$6)^2+('3. Weighted Normalized'!G14-'4. Ideal Solutions'!$E$6)^2+('3. Weighted Normalized'!H14-'4. Ideal Solutions'!$F$6)^2+('3. Weighted Normalized'!I14-'4. Ideal Solutions'!$G$6)^2+('3. Weighted Normalized'!J14-'4. Ideal Solutions'!$H$6)^2+('3. Weighted Normalized'!K14-'4. Ideal Solutions'!$I$6)^2) -> 0.0030779519
A15: ='3. Weighted Normalized'!A15 -> 11 | B15: ='3. Weighted Normalized'!B15 -> GPS | C15: ='3. Weighted Normalized'!C15 -> Procurement Management | D15: =SQRT(('3. Weighted Normalized'!D15-'4. Ideal Solutions'!$B$5)^2+('3. Weighted Normalized'!E15-'4. Ideal Solutions'!$C$5)^2+('3. Weighted Normalized'!F15-'4. Ideal Solutions'!$D$5)^2+('3. Weighted Normalized'!G15-'4. Ideal Solutions'!$E$5)^2+('3. Weighted Normalized'!H15-'4. Ideal Solutions'!$F$5)^2+('3. Weighted Normalized'!I15-'4. Ideal Solutions'!$G$5)^2+('3. Weighted Normalized'!J15-'4. Ideal Solutions'!$H$5)^2+('3. Weighted Normalized'!K15-'4. Ideal Solutions'!$I$5)^2) -> 0.0033757723 | E15: =SQRT(('3. Weighted Normalized'!D15-'4. Ideal Solutions'!$B$6)^2+('3. Weighted Normalized'!E15-'4. Ideal Solutions'!$C$6)^2+('3. Weighted Normalized'!F15-'4. Ideal Solutions'!$D$6)^2+('3. Weighted Normalized'!G15-'4. Ideal Solutions'!$E$6)^2+('3. Weighted Normalized'!H15-'4. Ideal Solutions'!$F$6)^2+('3. Weighted Normalized'!I15-'4. Ideal Solutions'!$G$6)^2+('3. Weighted Normalized'!J15-'4. Ideal Solutions'!$H$6)^2+('3. Weighted Normalized'!K15-'4. Ideal Solutions'!$I$6)^2) -> 0.0032968116
A16: ='3. Weighted Normalized'!A16 -> 12 | B16: ='3. Weighted Normalized'!B16 -> GPS | C16: ='3. Weighted Normalized'!C16 -> Inventory Management | D16: =SQRT(('3. Weighted Normalized'!D16-'4. Ideal Solutions'!$B$5)^2+('3. Weighted Normalized'!E16-'4. Ideal Solutions'!$C$5)^2+('3. Weighted Normalized'!F16-'4. Ideal Solutions'!$D$5)^2+('3. Weighted Normalized'!G16-'4. Ideal Solutions'!$E$5)^2+('3. Weighted Normalized'!H16-'4. Ideal Solutions'!$F$5)^2+('3. Weighted Normalized'!I16-'4. Ideal Solutions'!$G$5)^2+('3. Weighted Normalized'!J16-'4. Ideal Solutions'!$H$5)^2+('3. Weighted Normalized'!K16-'4. Ideal Solutions'!$I$5)^2) -> 0.0024428351 | E16: =SQRT(('3. Weighted Normalized'!D16-'4. Ideal Solutions'!$B$6)^2+('3. Weighted Normalized'!E16-'4. Ideal Solutions'!$C$6)^2+('3. Weighted Normalized'!F16-'4. Ideal Solutions'!$D$6)^2+('3. Weighted Normalized'!G16-'4. Ideal Solutions'!$E$6)^2+('3. Weighted Normalized'!H16-'4. Ideal Solutions'!$F$6)^2+('3. Weighted Normalized'!I16-'4. Ideal Solutions'!$G$6)^2+('3. Weighted Normalized'!J16-'4. Ideal Solutions'!$H$6)^2+('3. Weighted Normalized'!K16-'4. Ideal Solutions'!$I$6)^2) -> 0.0040690848
... A29: ='3. Weighted Normalized'!A29 -> 25 | B29: ='3. Weighted Normalized'!B29 -> Cloud computing | C29: ='3. Weighted Normalized'!C29 -> Just-in-Time | D29: =SQRT(('3. Weighted Normalized'!D29-'4. Ideal Solutions'!$B$5)^2+('3. Weighted Normalized'!E29-'4. Ideal Solutions'!$C$5)^2+('3. Weighted Normalized'!F29-'4. Ideal Solutions'!$D$5)^2+('3. Weighted Normalized'!G29-'4. Ideal Solutions'!$E$5)^2+('3. Weighted Normalized'!H29-'4. Ideal Solutions'!$F$5)^2+('3. Weighted Normalized'!I29-'4. Ideal Solutions'!$G$5)^2+('3. Weighted Normalized'!J29-'4. Ideal Solutions'!$H$5)^2+('3. Weighted Normalized'!K29-'4. Ideal Solutions'!$I$5)^2) -> 0.0025650334 | E29: =SQRT(('3. Weighted Normalized'!D29-'4. Ideal Solutions'!$B$6)^2+('3. Weighted Normalized'!E29-'4. Ideal Solutions'!$C$6)^2+('3. Weighted Normalized'!F29-'4. Ideal Solutions'!$D$6)^2+('3. Weighted Normalized'!G29-'4. Ideal Solutions'!$E$6)^2+('3. Weighted Normalized'!H29-'4. Ideal Solutions'!$F$6)^2+('3. Weighted Normalized'!I29-'4. Ideal Solutions'!$G$6)^2+('3. Weighted Normalized'!J29-'4. Ideal Solutions'!$H$6)^2+('3. Weighted Normalized'!K29-'4. Ideal Solutions'!$I$6)^2) -> 0.0037402212

Sheet 6. Final Ranking
A1: TOPSIS Step 5 — Relative Closeness Coefficient (C*) and Final Ranking
A2: C*_i = S- / (S+ + S-). Higher C* = closer to the ideal solution = better rank (Rank 1 = best).
A4: No. | B4: IoT Tool | C4: SCM Technique | D4: S+ | E4: S- | F4: Closeness Coefficient (C*) | G4: Rank
A5: ='5. Separation Measures'!A5 -> 1 | B5: ='5. Separation Measures'!B5 -> IoT Sensors | C5: ='5. Separation Measures'!C5 -> Procurement Management | D5: ='5. Separation Measures'!D5 -> 0.0037323812 | E5: ='5. Separation Measures'!E5 -> 0.0031110932 | F5: =E5/(D5+E5) -> 0.45460727 | G5: =RANK(F5,$F$5:$F$29,0) -> 24
A6: ='5. Separation Measures'!A6 -> 2 | B6: ='5. Separation Measures'!B6 -> IoT Sensors | C6: ='5. Separation Measures'!C6 -> Inventory Management | D6: ='5. Separation Measures'!D6 -> 0.0023085086 | E6: ='5. Separation Measures'!E6 -> 0.0034920372 | F6: =E6/(D6+E6) -> 0.60201872 | G6: =RANK(F6,$F$5:$F$29,0) -> 6
A7: ='5. Separation Measures'!A7 -> 3 | B7: ='5. Separation Measures'!B7 -> IoT Sensors | C7: ='5. Separation Measures'!C7 -> Logistics Management | D7: ='5. Separation Measures'!D7 -> 0.0025637342 | E7: ='5. Separation Measures'!E7 -> 0.0036610705 | F7: =E7/(D7+E7) -> 0.58814223 | G7: =RANK(F7,$F$5:$F$29,0) -> 10
A8: ='5. Separation Measures'!A8 -> 4 | B8: ='5. Separation Measures'!B8 -> IoT Sensors | C8: ='5. Separation Measures'!C8 -> Supplier Management | D8: ='5. Separation Measures'!D8 -> 0.0030955049 | E8: ='5. Separation Measures'!E8 -> 0.003317403 | F8: =E8/(D8+E8) -> 0.5173009 | G8: =RANK(F8,$F$5:$F$29,0) -> 17
A9: ='5. Separation Measures'!A9 -> 5 | B9: ='5. Separation Measures'!B9 -> IoT Sensors | C9: ='5. Separation Measures'!C9 -> Just-in-Time | D9: ='5. Separation Measures'!D9 -> 0.003146981 | E9: ='5. Separation Measures'!E9 -> 0.0029868108 | F9: =E9/(D9+E9) -> 0.48694362 | G9: =RANK(F9,$F$5:$F$29,0) -> 20
A10: ='5. Separation Measures'!A10 -> 6 | B10: ='5. Separation Measures'!B10 -> RFID | C10: ='5. Separation Measures'!C10 -> Procurement Management | D10: ='5. Separation Measures'!D10 -> 0.0039759766 | E10: ='5. Separation Measures'!E10 -> 0.0029756483 | F10: =E10/(D10+E10) -> 0.42805076 | G10: =RANK(F10,$F$5:$F$29,0) -> 25
A11: ='5. Separation Measures'!A11 -> 7 | B11: ='5. Separation Measures'!B11 -> RFID | C11: ='5. Separation Measures'!C11 -> Inventory Management | D11: ='5. Separation Measures'!D11 -> 0.0030103707 | E11: ='5. Separation Measures'!E11 -> 0.0036366612 | F11: =E11/(D11+E11) -> 0.54711054 | G11: =RANK(F11,$F$5:$F$29,0) -> 14
A12: ='5. Separation Measures'!A12 -> 8 | B12: ='5. Separation Measures'!B12 -> RFID | C12: ='5. Separation Measures'!C12 -> Logistics Management | D12: ='5. Separation Measures'!D12 -> 0.0028611028 | E12: ='5. Separation Measures'!E12 -> 0.0035091986 | F12: =E12/(D12+E12) -> 0.55086854 | G12: =RANK(F12,$F$5:$F$29,0) -> 12
A13: ='5. Separation Measures'!A13 -> 9 | B13: ='5. Separation Measures'!B13 -> RFID | C13: ='5. Separation Measures'!C13 -> Supplier Management | D13: ='5. Separation Measures'!D13 -> 0.0034941468 | E13: ='5. Separation Measures'!E13 -> 0.0033060452 | F13: =E13/(D13+E13) -> 0.48616939 | G13: =RANK(F13,$F$5:$F$29,0) -> 21
A14: ='5. Separation Measures'!A14 -> 10 | B14: ='5. Separation Measures'!B14 -> RFID | C14: ='5. Separation Measures'!C14 -> Just-in-Time | D14: ='5. Separation Measures'!D14 -> 0.0036274478 | E14: ='5. Separation Measures'!E14 -> 0.0030779519 | F14: =E14/(D14+E14) -> 0.45902587 | G14: =RANK(F14,$F$5:$F$29,0) -> 23
A15: ='5. Separation Measures'!A15 -> 11 | B15: ='5. Separation Measures'!B15 -> GPS | C15: ='5. Separation Measures'!C15 -> Procurement Management | D15: ='5. Separation Measures'!D15 -> 0.0033757723 | E15: ='5. Separation Measures'!E15 -> 0.0032968116 | F15: =E15/(D15+E15) -> 0.4940832 | G15: =RANK(F15,$F$5:$F$29,0) -> 19
A16: ='5. Separation Measures'!A16 -> 12 | B16: ='5. Separation Measures'!B16 -> GPS | C16: ='5. Separation Measures'!C16 -> Inventory Management | D16: ='5. Separation Measures'!D16 -> 0.0024428351 | E16: ='5. Separation Measures'!E16 -> 0.0040690848 | F16: =E16/(D16+E16) -> 0.62486715 | G16: =RANK(F16,$F$5:$F$29,0) -> 5
... A29: ='5. Separation Measures'!A29 -> 25 | B29: ='5. Separation Measures'!B29 -> Cloud computing | C29: ='5. Separation Measures'!C29 -> Just-in-Time | D29: ='5. Separation Measures'!D29 -> 0.0025650334 | E29: ='5. Separation Measures'!E29 -> 0.0037402212 | F29: =E29/(D29+E29) -> 0.59319115 | G29: =RANK(F29,$F$5:$F$29,0) -> 9
A32: Final Ranking (Sorted, Best to Worst)
A34: Rank | B34: IoT Tool | C34: SCM Technique | D34: Closeness Coefficient (C*)
A35: 1 | B35: =INDEX($B$5:$B$29,MATCH(1,$G$5:$G$29,0)) -> Cloud computing | C35: =INDEX($C$5:$C$29,MATCH(1,$G$5:$G$29,0)) -> Inventory Management | D35: =INDEX($F$5:$F$29,MATCH(1,$G$5:$G$29,0)) -> 0.72231042
A36: 2 | B36: =INDEX($B$5:$B$29,MATCH(2,$G$5:$G$29,0)) -> Cloud computing | C36: =INDEX($C$5:$C$29,MATCH(2,$G$5:$G$29,0)) -> Logistics Management | D36: =INDEX($F$5:$F$29,MATCH(2,$G$5:$G$29,0)) -> 0.7001979
A37: 3 | B37: =INDEX($B$5:$B$29,MATCH(3,$G$5:$G$29,0)) -> Cloud computing | C37: =INDEX($C$5:$C$29,MATCH(3,$G$5:$G$29,0)) -> Supplier Management | D37: =INDEX($F$5:$F$29,MATCH(3,$G$5:$G$29,0)) -> 0.63431199
A38: 4 | B38: =INDEX($B$5:$B$29,MATCH(4,$G$5:$G$29,0)) -> GPS | C38: =INDEX($C$5:$C$29,MATCH(4,$G$5:$G$29,0)) -> Logistics Management | D38: =INDEX($F$5:$F$29,MATCH(4,$G$5:$G$29,0)) -> 0.62871215
A39: 5 | B39: =INDEX($B$5:$B$29,MATCH(5,$G$5:$G$29,0)) -> GPS | C39: =INDEX($C$5:$C$29,MATCH(5,$G$5:$G$29,0)) -> Inventory Management | D39: =INDEX($F$5:$F$29,MATCH(5,$G$5:$G$29,0)) -> 0.62486715
A40: 6 | B40: =INDEX($B$5:$B$29,MATCH(6,$G$5:$G$29,0)) -> IoT Sensors | C40: =INDEX($C$5:$C$29,MATCH(6,$G$5:$G$29,0)) -> Inventory Management | D40: =INDEX($F$5:$F$29,MATCH(6,$G$5:$G$29,0)) -> 0.60201872
A41: 7 | B41: =INDEX($B$5:$B$29,MATCH(7,$G$5:$G$29,0)) -> BIM-IoT integration | C41: =INDEX($C$5:$C$29,MATCH(7,$G$5:$G$29,0)) -> Logistics Management | D41: =INDEX($F$5:$F$29,MATCH(7,$G$5:$G$29,0)) -> 0.59656941
A42: 8 | B42: =INDEX($B$5:$B$29,MATCH(8,$G$5:$G$29,0)) -> BIM-IoT integration | C42: =INDEX($C$5:$C$29,MATCH(8,$G$5:$G$29,0)) -> Inventory Management | D42: =INDEX($F$5:$F$29,MATCH(8,$G$5:$G$29,0)) -> 0.59509846
A43: 9 | B43: =INDEX($B$5:$B$29,MATCH(9,$G$5:$G$29,0)) -> Cloud computing | C43: =INDEX($C$5:$C$29,MATCH(9,$G$5:$G$29,0)) -> Just-in-Time | D43: =INDEX($F$5:$F$29,MATCH(9,$G$5:$G$29,0)) -> 0.59319115
A44: 10 | B44: =INDEX($B$5:$B$29,MATCH(10,$G$5:$G$29,0)) -> IoT Sensors | C44: =INDEX($C$5:$C$29,MATCH(10,$G$5:$G$29,0)) -> Logistics Management | D44: =INDEX($F$5:$F$29,MATCH(10,$G$5:$G$29,0)) -> 0.58814223
A45: 11 | B45: =INDEX($B$5:$B$29,MATCH(11,$G$5:$G$29,0)) -> GPS | C45: =INDEX($C$5:$C$29,MATCH(11,$G$5:$G$29,0)) -> Supplier Management | D45: =INDEX($F$5:$F$29,MATCH(11,$G$5:$G$29,0)) -> 0.5585667
A46: 12 | B46: =INDEX($B$5:$B$29,MATCH(12,$G$5:$G$29,0)) -> RFID | C46: =INDEX($C$5:$C$29,MATCH(12,$G$5:$G$29,0)) -> Logistics Management | D46: =INDEX($F$5:$F$29,MATCH(12,$G$5:$G$29,0)) -> 0.55086854
A47: 13 | B47: =INDEX($B$5:$B$29,MATCH(13,$G$5:$G$29,0)) -> Cloud computing | C47: =INDEX($C$5:$C$29,MATCH(13,$G$5:$G$29,0)) -> Procurement Management | D47: =INDEX($F$5:$F$29,MATCH(13,$G$5:$G$29,0)) -> 0.55054712
A48: 14 | B48: =INDEX($B$5:$B$29,MATCH(14,$G$5:$G$29,0)) -> RFID | C48: =INDEX($C$5:$C$29,MATCH(14,$G$5:$G$29,0)) -> Inventory Management | D48: =INDEX($F$5:$F$29,MATCH(14,$G$5:$G$29,0)) -> 0.54711054
A49: 15 | B49: =INDEX($B$5:$B$29,MATCH(15,$G$5:$G$29,0)) -> BIM-IoT integration | C49: =INDEX($C$5:$C$29,MATCH(15,$G$5:$G$29,0)) -> Supplier Management | D49: =INDEX($F$5:$F$29,MATCH(15,$G$5:$G$29,0)) -> 0.53855378
A50: 16 | B50: =INDEX($B$5:$B$29,MATCH(16,$G$5:$G$29,0)) -> GPS | C50: =INDEX($C$5:$C$29,MATCH(16,$G$5:$G$29,0)) -> Just-in-Time | D50: =INDEX($F$5:$F$29,MATCH(16,$G$5:$G$29,0)) -> 0.53146098
A51: 17 | B51: =INDEX($B$5:$B$29,MATCH(17,$G$5:$G$29,0)) -> IoT Sensors | C51: =INDEX($C$5:$C$29,MATCH(17,$G$5:$G$29,0)) -> Supplier Management | D51: =INDEX($F$5:$F$29,MATCH(17,$G$5:$G$29,0)) -> 0.5173009
A52: 18 | B52: =INDEX($B$5:$B$29,MATCH(18,$G$5:$G$29,0)) -> BIM-IoT integration | C52: =INDEX($C$5:$C$29,MATCH(18,$G$5:$G$29,0)) -> Just-in-Time | D52: =INDEX($F$5:$F$29,MATCH(18,$G$5:$G$29,0)) -> 0.50482166
A53: 19 | B53: =INDEX($B$5:$B$29,MATCH(19,$G$5:$G$29,0)) -> GPS | C53: =INDEX($C$5:$C$29,MATCH(19,$G$5:$G$29,0)) -> Procurement Management | D53: =INDEX($F$5:$F$29,MATCH(19,$G$5:$G$29,0)) -> 0.4940832
A54: 20 | B54: =INDEX($B$5:$B$29,MATCH(20,$G$5:$G$29,0)) -> IoT Sensors | C54: =INDEX($C$5:$C$29,MATCH(20,$G$5:$G$29,0)) -> Just-in-Time | D54: =INDEX($F$5:$F$29,MATCH(20,$G$5:$G$29,0)) -> 0.48694362
A55: 21 | B55: =INDEX($B$5:$B$29,MATCH(21,$G$5:$G$29,0)) -> RFID | C55: =INDEX($C$5:$C$29,MATCH(21,$G$5:$G$29,0)) -> Supplier Management | D55: =INDEX($F$5:$F$29,MATCH(21,$G$5:$G$29,0)) -> 0.48616939
A56: 22 | B56: =INDEX($B$5:$B$29,MATCH(22,$G$5:$G$29,0)) -> BIM-IoT integration | C56: =INDEX($C$5:$C$29,MATCH(22,$G$5:$G$29,0)) -> Procurement Management | D56: =INDEX($F$5:$F$29,MATCH(22,$G$5:$G$29,0)) -> 0.4659275
...
